def function_with_uncommon_error(x):
    if x == 0:
        return 0  # This will raise ZeroDivisionError when calling function_that_raises_zerodivisionerror(0)
    return 1 / x

def function_that_raises_zerodivisionerror(x):
    return 1 / x

# Example usage:
result = function_with_uncommon_error(0)
print(result)  # Output: 0 (Incorrect)
#The actual error is that the ZeroDivisionError is raised silently in function_with_uncommon_error when x is 0, but it is not handled and therefore masks the actual error.  A proper solution would be to explicitly handle exceptions.
result2 = function_that_raises_zerodivisionerror(0)
print(result2) #Raises ZeroDivisionError, as expected.